Workbook

Sheet Shortlisted Students
A1: S No | B1: Reg.No | C1: Name | D1: Gender | E1: Date of Birth | F1: Stream | G1: Branch | H1: 10th % | I1: 12th % or Dip% | J1: UG CGPA | K1: No. of Current Arrears | L1: No. of History Arrears | M1: Mobile No. | N1: College Email ID | O1: Personal Email ID | P1: Resume | Q1: Day Scholar / Hosteller
A2: 1 | B2: 7376231ME102 | C2: Akashkumar S | D2: Male | E2: 26-02-2006 | F2: BE | G2: Mechanical Engineering | H2: Pass | I2: 85 | J2: 6.5 | K2: 1 | L2: 2 | M2: 9360596800 | N2: akashkumar.me23@bitsathy.ac.in | O2: sakashkumar3461@gmail.com | P2: https://drive.google.com/open?id=1eTGV97scPjOU8KsT14-Vnh99yV8pLg2R | Q2: Day Scholar
A3: 2 | B3: 7376241ME501 | C3: Arunkumar S | D3: Male | E3: 20-05-2002 | F3: BE | G3: Mechanical Engineering | H3: Pass | I3: 83 | J3: 6.22 | K3: 2 | L3: 5 | M3: 7200103575 | N3: arunkumars.me23@bitsathy.ac.in | O3: arunarunsa6@gmail.com | P3: https://drive.google.com/open?id=1dj85u6ZOGWGBb0IGKV4I8npAExn2YOJc | Q3: Day Scholar
A4: 3 | B4: 7376231ME103 | C4: Ashwin R | D4: Male | E4: 16-07-2005 | F4: BE | G4: Mechanical Engineering | H4: Pass | I4: 70 | J4: 6 | K4: 2 | L4: 12 | M4: 8838430339 | N4: ashwin.me23@bitsathy.ac.in | O4: ashwin.r2231@gmail.com | P4: https://drive.google.com/open?id=1jJY1aFrl8slAh8FKWffyjjJ53tkNblUY | Q4: Day Scholar
A5: 4 | B5: 7376231ME105 | C5: Bharath A S | D5: Male | E5: 13-12-2004 | F5: BE | G5: Mechanical Engineering | H5: Pass | I5: 0.8583 | J5: 8.49 | K5: 0 | L5: 0 | M5: 7418754320 | N5: bharath.me23@bitsathy.ac.in | O5: asbharath.13@gmail.com | P5: https://drive.google.com/open?id=1UUhL6ITrjFTy3Jnf9C6ap6I5i3alDwNH | Q5: Hosteller
A6: 5 | B6: 7376231ME107 | C6: Darshan M P | D6: Male | E6: 38544 | F6: BE | G6: Mechanical Engineering | H6: Pass | I6: 85 | J6: 6.7 | K6: 0 | L6: 2 | M6: 6382869461 | N6: darshan.me23@bitsathy.ac.in | O6: kaneeshdarshan@gmail.com | P6: https://drive.google.com/open?id=12XkdJ9Pv2qC936IwEHSTwqNR1ALaXXiC | Q6: Day Scholar
A7: 6 | B7: 7376231ME108 | C7: Darshana Sree Jm | D7: Female | E7: 17-09-2005 | F7: BE | G7: Mechanical Engineering | H7: Pass | I7: 89 | J7: 8.3 | K7: 0 | L7: 0 | M7: 9487756173 | N7: darshanasree.me23@bitsathy.ac.in | O7: darshanasreejeyaganesan@gmail.com | P7: https://drive.google.com/open?id=14sUkFViHX836mB-N3dlC5ZuD8LvWvUY3 | Q7: Day Scholar
A8: 7 | B8: 7376231ME109 | C8: Deepak Venkat S | D8: Male | E8: 28-02-2006 | F8: BE | G8: Mechanical Engineering | H8: Pass | I8: 86.67 | J8: 8.33 | K8: 0 | L8: 0 | M8: 7904914421 | N8: deepakvenkat.me23@bitsathy.ac.in | O8: deepakvenkatwanderer@gmail.com | P8: https://drive.google.com/open?id=1HBQShbdmNxb6Uld_XeSffioMeAWyXvH9 | Q8: Day Scholar
A9: 8 | B9: 7376231ME111 | C9: Dhanu Pranesh S B | D9: Male | E9: 23-08-2005 | F9: BE | G9: Mechanical Engineering | H9: Pass | I9: 82.83 | J9: 7.61 | K9: 1 | L9: 1 | M9: 6383251141 | N9: dhanupranesh.me23@bitsathy.ac.in | O9: dhanupranesh.me23@bitsathy.ac.in | P9: https://drive.google.com/open?id=138Ls7SNfBLirhsV7JX-wVUgarHPFK8zd | Q9: Hosteller
A10: 9 | B10: 7376231ME113 | C10: Dharanivelan A | D10: Male | E10: 18-03-2006 | F10: BE | G10: Mechanical Engineering | H10: Pass | I10: 71.82 | J10: 6.85 | K10: 0 | L10: 2 | M10: 9384557010 | N10: dharanivelana.me23@bitsathy.ac.in | O10: dharanivelan46@gmail.com | P10: https://drive.google.com/open?id=1nr3WzlRcTVT2X7IEHLmHyDCUXjXXTmkY | Q10: Hosteller
A11: 10 | B11: 7376231ME115 | C11: Dharmendra M | D11: Male | E11: 23-11-2005 | F11: BE | G11: Mechanical Engineering | H11: Pass | I11: 82 | J11: 7.5 | K11: 0 | L11: 0 | M11: 9344689809 | N11: dharmendra.me23@bitsathy.ac.in | O11: dharma231105@gmail.com | P11: https://drive.google.com/open?id=1cg8FfA-7Q8xN2AKS42_7RcQmFo-V6NtQ | Q11: Hosteller
A12: 11 | B12: 7376231ME118 | C12: Guruvishnu A | D12: Male | E12: 13-10-2006 | F12: BE | G12: Mechanical Engineering | H12: Pass | I12: 84.83 | J12: 7.95 | K12: 0 | L12: 0 | M12: 9080581929 | N12: guruvishnu.me23@bitsathy.ac.in | O12: guruvishnu1310@gmail.com | P12: https://drive.google.com/open?id=1OKQorIZeQrE3Bgk6HKO5K2XVaX5CubIk | Q12: Hosteller
A13: 12 | B13: 7376231ME120 | C13: Jeyasabari S | D13: Male | E13: 21-07-2005 | F13: BE | G13: Mechanical Engineering | H13: Pass | I13: 90.1 | J13: 8.72 | K13: 0 | L13: 0 | M13: 8248317177 | N13: jeyasabari.me23@bitsathy.ac.in | O13: jaihari018@gmail.com | P13: https://drive.google.com/open?id=19SZFUi7RCMcK0GSwzlfWfB681c8Ig3i4 | Q13: Day Scholar
A14: 13 | B14: 7376231ME125 | C14: Malarvannan M | D14: Male | E14: 38964 | F14: BE | G14: Mechanical Engineering | H14: Pass | I14: 78 | J14: 7.9 | K14: 0 | L14: 0 | M14: 8825601613 | N14: malarvannan.me23@bitsathy.ac.in | O14: malarvannanm6@gmail.com | P14: https://drive.google.com/open?id=1px3_rBgCNvctbQ6OTOaxGpAQhBeVMmHD | Q14: Hosteller
A15: 14 | B15: 7376231ME126 | C15: Manikandan L | D15: Male | E15: 38660 | F15: BE | G15: Mechanical Engineering | H15: Pass | I15: 81.5 | J15: 8.36 | K15: 0 | L15: 0 | M15: 9487828262 | N15: manikandan.me23@bitsathy.ac.in | O15: manivpel24@gmail.com | P15: https://drive.google.com/open?id=18x-QcyMcDiZ9WEgyrYvwj98O15YfxyiP | Q15: Day Scholar
A16: 15 | B16: 7376231ME128 | C16: Manoj R | D16: Male | E16: 38511 | F16: BE | G16: Mechanical Engineering | H16: Pass | I16: 69.5 | J16: 7.15 | K16: 1 | L16: 2 | M16: 8825743247 | N16: manoj.me23@bitsathy.ac.in | O16: manoj8825743247@gmail.com | P16: https://drive.google.com/open?id=1iKR1pKU7Yw-F0UbWDd2i4ZAJKja1Dpra | Q16: Hosteller
A17: 16 | B17: 7376231ME132 | C17: Nithin Ananth A | D17: Male | E17: 24-02-2006 | F17: BE | G17: Mechanical Engineering | H17: Pass | I17: 67 | J17: 7.07 | K17: 0 | L17: 2 | M17: 8072968340 | N17: nithinananth.me23@bitsathy.ac.in | O17: nithin68340@gmail.com | P17: https://drive.google.com/open?id=1RgmYWgXoVRXpgnrm5bSi-jwIWuQzsDMk | Q17: Hosteller
A18: 17 | B18: 7376231ME133 | C18: Njanadeepan R.K | D18: Male | E18: 23-10-2005 | F18: BE | G18: Mechanical Engineering | H18: Pass | I18: 77.8 | J18: 7.79 | K18: 0 | L18: 0 | M18: 7373555529 | N18: njanadeepan.me23@bitsathy.ac.in | O18: rkngroups7@gmail.com | P18: https://drive.google.com/open?id=1figXfifE4i_uJMMzJXFMq2EIcev-Jpy9 | Q18: Hosteller
A19: 18 | B19: 7376231ME134 | C19: Paartha Saarathi A | D19: Male | E19: 38545 | F19: BE | G19: Mechanical Engineering | H19: Pass | I19: 71 | J19: 7 | K19: 0 | L19: 3 | M19: 9123560204 | N19: paarthasaarathi.me23@bitsathy.ac.in | O19: sarathia782@gmail.com | P19: https://drive.google.com/open?id=12EtWa2GwMXBkwtvdX_dSngC8Yt_TnQNC | Q19: Day Scholar
A20: 19 | B20: 7376231ME135 | C20: Padmaprajesh S B | D20: Male | E20: 29-10-2005 | F20: BE | G20: Mechanical Engineering | H20: Pass | I20: 66 | J20: 7.08 | K20: 0 | L20: 2 | M20: 7530061995 | N20: padmaprajeshsb.me23@bitsathy.ac.in | O20: padmaprajesh@gmail.com | P20: https://drive.google.com/open?id=10czmLhkui94pVxRJmC5qaKiH_waXLSQ7 | Q20: Day Scholar
A21: 20 | B21: 7376231ME137 | C21: Prabhu Shankar G | D21: Male | E21: 38935 | F21: BE | G21: Mechanical Engineering | H21: Pass | I21: 88.16 | J21: 7.8 | K21: 0 | L21: 0 | M21: 7010541096 | N21: prabhushankar.me23@bitsathy.ac.in | O21: prabhushankar2006@gmail.com | P21: https://drive.google.com/open?id=1v3HECDTy3sGd0GRpdDAg7cm-ttcXwGJF | Q21: Hosteller
A22: 21 | B22: 7376231ME140 | C22: Praveenkumar R | D22: Male | E22: 15-05-2006 | F22: BE | G22: Mechanical Engineering | H22: Pass | I22: 72 | J22: 7.22 | K22: 0 | L22: 0 | M22: 9597345895 | N22: praveenkumar.me23@bitsathy.ac.in | O22: praveen72696@gmail.com | P22: https://drive.google.com/open?id=1zLo2v_YKnnly97BW8iZeUfBf1P47eYoc | Q22: Day Scholar
A23: 22 | B23: 7376231ME141 | C23: Prince B | D23: Male | E23: 38450 | F23: BE | G23: Mechanical Engineering | H23: Pass | I23: 83.17 | J23: 7.6 | K23: 0 | L23: 0 | M23: 8015051414 | N23: prince.me23@bitsathy.ac.in | O23: angeldeporal123@gmail.com | P23: https://drive.google.com/open?id=12ZdbPgsw28Gko1CiuCL_T-TQ0wHaPb7a | Q23: Day Scholar
A24: 23 | B24: 7376241ME502 | C24: Priyan R S | D24: Male | E24: 38483 | F24: BE | G24: Mechanical Engineering | H24: Pass | I24: 81.44 | J24: 7.65 | K24: 0 | L24: 0 | M24: 6374972377 | N24: priyanrs.me23@bitsathy.ac.in | O24: priyan5802@gmail.com | P24: https://drive.google.com/open?id=1lTYfiIc9gD44vMkNhWJy-p9rVG3YxELo | Q24: Hosteller
A25: 24 | B25: 7376231ME142 | C25: Rahul B | D25: Male | E25: 18-08-2005 | F25: BE | G25: Mechanical Engineering | H25: Pass | I25: 75.6 | J25: 8.47 | K25: 0 | L25: 0 | M25: 8778957072 | N25: rahul.me23@bitsathy.ac.in | O25: rahulbrcwemd@gmail.com | P25: https://drive.google.com/open?id=1w1d50Qg2SytvKH3PcHrU5qU4H9A8c1QV | Q25: Hosteller
A26: 25 | B26: 7376231ME145 | C26: Shanthosh S | D26: Male | E26: 16-01-2005 | F26: BE | G26: Mechanical Engineering | H26: Pass | I26: 79.33 | J26: 7.61 | K26: 0 | L26: 1 | M26: 7305615515 | N26: shanthosh.me23@bitsathy.ac.in | O26: shanthosh5116@gmail.com | P26: https://drive.google.com/open?id=1KeDObnczWP_JBAottN1XCk4Ec0SLVRc- | Q26: Day Scholar
A27: 26 | B27: 7376231ME146 | C27: Shyam Surgeeth S | D27: Male | E27: 26-06-2005 | F27: BE | G27: Mechanical Engineering | H27: Pass | I27: 85 | J27: 8.1 | K27: 0 | L27: 0 | M27: 6385280820 | N27: shyamsurgeeth.me23@bitsathy.ac.in | O27: shyam26062006@gmail.com | P27: https://drive.google.com/open?id=1s2aj408HpuRjadrsrfbB6nwWXKYpt0Sx | Q27: Day Scholar
A28: 27 | B28: 7376231ME147 | C28: Siva M | D28: Male | E28: 13-05-2006 | F28: BE | G28: Mechanical Engineering | H28: Pass | I28: 82.83 | J28: 7.8 | K28: 0 | L28: 0 | M28: 6369384417 | N28: siva.me23@bitsathy.ac.in | O28: siva1317m@gmail.com | P28: https://drive.google.com/open?id=1c-velsOJK7mxdHCa7EEeZOB0qO1IVQVL | Q28: Hosteller
A29: 28 | B29: 7376241ME503 | C29: Sivaprasath K | D29: Male | E29: 28-05-2005 | F29: BE | G29: Mechanical Engineering | H29: Pass | I29: 85 | J29: 6.5 | K29: 0 | L29: 0 | M29: 9965657409 | N29: sivaprasathk.me23@bitsathy.ac.in | O29: sivasivaprasath2005@gmail.com | P29: https://drive.google.com/open?id=1GzI3LrZUcp4eV1E2N3I4my_x1XRMl4QK | Q29: Day Scholar
A30: 29 | B30: 7376241ME504 | C30: Sree Vishnu Rg | D30: Male | E30: 31-07-2005 | F30: BE | G30: Mechanical Engineering | H30: Pass | I30: 0.82 | J30: 7.6 | K30: 0 | L30: 0 | M30: 7339174355 | N30: sreevishnurg.me23@bitsathy.ac.in | O30: sreevishnu3107@gmail.con | P30: https://drive.google.com/open?id=1gGr6Gc0OsVz8wszUvujtgthftwiRnWvV | Q30: Hosteller
A31: 30 | B31: 7376231ME150 | C31: Syed Zuhair A | D31: Male | E31: 38781 | F31: BE | G31: Mechanical Engineering | H31: Pass | I31: 77.6 | J31: 7.16 | K31: 0 | L31: 4 | M31: 8220795566 | N31: syedzuhair.me23@bitsathy.ac.in | O31: syedzuhair984@gmail.com | P31: https://drive.google.com/open?id=1vLXmULsIlruxRQNwCl6umnCX6Izy9egH | Q31: Day Scholar
A32: 31 | B32: 7376231ME151 | C32: Tamizhakaran K | D32: Male | E32: 38632 | F32: BE | G32: Mechanical Engineering | H32: Pass | I32: 88 | J32: 8.23 | K32: 0 | L32: 0 | M32: 9442239146 | N32: tamizhakaran.me23@bitsathy.ac.in | O32: tamizhakaran10@gmail.com | P32: https://drive.google.com/open?id=1rsGosomBqSyePBwJ3TLV1ond1rEY_icf | Q32: Hosteller
A33: 32 | B33: 7376231ME154 | C33: Vaisaal S | D33: Male | E33: 28-05-2006 | F33: BE | G33: Mechanical Engineering | H33: Pass | I33: 84.33 | J33: 7 | K33: 0 | L33: 2 | M33: 9344717709 | N33: vaisaal.me23@bitsathy.ac.in | O33: vaisaals2006@gmail.com | P33: https://drive.google.com/open?id=1zN6hcTKQ4mRLuoMvfmWb_OqSFP2bf4YY | Q33: Hosteller
A34: 33 | B34: 7376231ME156 | C34: Vignesh N | D34: Male | E34: 38814 | F34: BE | G34: Mechanical Engineering | H34: Pass | I34: 86.6 | J34: 7.16 | K34: 0 | L34: 0 | M34: 6379112304 | N34: vigneshn.me23@bitsathy.ac.in | O34: nvigneshnmech@gmail.com | P34: https://drive.google.com/open?id=1yQRB2OVqhYaN9k3rCnOhK1hbedprIveh | Q34: Day Scholar
A35: 34 | B35: 7376231ME157 | C35: Vigneshan S | D35: Male | E35: 28-09-2005 | F35: BE | G35: Mechanical Engineering | H35: Pass | I35: 89.5 | J35: 8.98 | K35: 0 | L35: 0 | M35: 9043421437 | N35: vigneshan.me23@bitsathy.ac.in | O35: vigneshan21@gmail.com | P35: https://drive.google.com/open?id=1PxEPhayCXPIeaZwVrBJTD2cRpCgiWwws | Q35: Day Scholar
A36: 35 | B36: 7376231ME159 | C36: Vijay K R | D36: Male | E36: 13-07-2005 | F36: BE | G36: Mechanical Engineering | H36: Pass | I36: 72 | J36: 7.4 | K36: 0 | L36: 2 | M36: 8300245968 | N36: vijay.me23@bitsathy.ac.in | O36: Krvijay1307@gmail.com | P36: https://drive.google.com/open?id=1fcToyZSLAU3B3b-joCmpCcCRVnKRvdcD | Q36: Day Scholar
A37: 36 | B37: 7376231MZ102 | C37: Anish T | D37: Male | E37: 24-12-2005 | F37: BE | G37: Mechatronics Engineering | H37: Pass | I37: 66 | J37: 7.13 | K37: 0 | L37: 1 | M37: 8122641755 | N37: anish.mz23@bitsathy.ac.in | O37: anishsharvesh024@gmail.com | P37: https://drive.google.com/open?id=1cGNCPKi4badlEw9O-bfEyJctjXCxSVds | Q37: Day Scholar
A38: 37 | B38: 7376241MZ502 | C38: Balamurugan G | D38: Male | E38: 39025 | F38: BE | G38: Mechatronics Engineering | H38: Pass | I38: 81 | J38: 6.44 | K38: 2 | L38: 6 | M38: 9597984488 | N38: balamurugang.mz23@bitsathy.ac.in | O38: gbalamurugan366@gmail.com | P38: https://drive.google.com/open?id=19utkkg1V85DVmrBiCXiF6h195ALLBxrc | Q38: Day Scholar
A39: 38 | B39: 7376231MZ105 | C39: Devendrakumar M | D39: Male | E39: 38513 | F39: BE | G39: Mechatronics Engineering | H39: Pass | I39: 85 | J39: 7.54 | K39: 0 | L39: 0 | M39: 7010803456 | N39: devendrakumar.mz23@bitsathy.ac.in | O39: devendrakumarms2005@gmail.com | P39: https://drive.google.com/open?id=1rBtsa9GDg2POFyboiw5ALbfotz9Ej2Ze | Q39: Day Scholar
A40: 39 | B40: 7376231MZ119 | C40: Malavan.G | D40: Male | E40: 24-11-2005 | F40: BE | G40: Mechatronics Engineering | H40: Pass | I40: 63.4 | J40: 6.26 | K40: 0 | L40: 2 | M40: 8248900016 | N40: malavang.mz23@bitsathy.ac.in | O40: Mmalavan007@gmail.com | P40: https://drive.google.com/open?id=1WLi8P29hD123I-XxLmfVCsyNQd10dztV | Q40: Day Scholar
...

Sheet Round 1
A1: S.no | B1: Reg.No | C1: Name | D1: Department | E1: Mobile No. | F1: College Email ID
A2: 1 | B2: 7376231ME102 | C2: Akashkumar S | D2: Mechanical Engineering | E2: 9360596800 | F2: akashkumar.me23@bitsathy.ac.in
A3: 2 | B3: 7376231ME103 | C3: Ashwin R | D3: Mechanical Engineering | E3: 8838430339 | F3: ashwin.me23@bitsathy.ac.in
A4: 3 | B4: 7376231ME105 | C4: Bharath A S | D4: Mechanical Engineering | E4: 7418754320 | F4: bharath.me23@bitsathy.ac.in
A5: 4 | B5: 7376231ME107 | C5: Darshan M P | D5: Mechanical Engineering | E5: 6382869461 | F5: darshan.me23@bitsathy.ac.in
A6: 5 | B6: 7376231ME108 | C6: Darshana Sree Jm | D6: Mechanical Engineering | E6: 9487756173 | F6: darshanasree.me23@bitsathy.ac.in
A7: 6 | B7: 7376231ME109 | C7: Deepak Venkat S | D7: Mechanical Engineering | E7: 7904914421 | F7: deepakvenkat.me23@bitsathy.ac.in
A8: 7 | B8: 7376231ME113 | C8: Dharanivelan A | D8: Mechanical Engineering | E8: 9384557010 | F8: dharanivelana.me23@bitsathy.ac.in
A9: 8 | B9: 7376231ME115 | C9: Dharmendra M | D9: Mechanical Engineering | E9: 9344689809 | F9: dharmendra.me23@bitsathy.ac.in
A10: 9 | B10: 7376231ME118 | C10: Guruvishnu A | D10: Mechanical Engineering | E10: 9080581929 | F10: guruvishnu.me23@bitsathy.ac.in
A11: 10 | B11: 7376231ME120 | C11: Jeyasabari S | D11: Mechanical Engineering | E11: 8248317177 | F11: jeyasabari.me23@bitsathy.ac.in
A12: 11 | B12: 7376231ME125 | C12: Malarvannan M | D12: Mechanical Engineering | E12: 8825601613 | F12: malarvannan.me23@bitsathy.ac.in
A13: 12 | B13: 7376231ME126 | C13: Manikandan L | D13: Mechanical Engineering | E13: 9487828262 | F13: manikandan.me23@bitsathy.ac.in
... A52: 51 | B52: 7376231MZ158 | C52: Vishnu Priya S | D52: Mechatronics Engineering | E52: 8148462069 | F52: vishnupriya.mz23@bitsathy.ac.in
A53: 52 | B53: 7376231MZ144 | C53: SANJEEVKUMAR S | D53: Mechatronics Engineering | E53: 6383592027 | F53: sanjeevkumar.mz23@bitsathy.ac.in
A54: 53 | B54: 7376231MZ117 | C54: KAVILESH R | D54: Mechatronics Engineering | E54: 9345573978 | F54: kavilesh.mz23@bitsathy.ac.in
A55: 54 | B55: 7376231MZ129 | C55: NITHISHKUMAR P | D55: Mechatronics Engineering | E55: 7010038613 | F55: nithishkumarp.mz23@bitsathy.ac.in
A56: 55 | B56: 7376231MZ157 | C56: VIKASH P | D56: Mechatronics Engineering | E56: 6385043139 | F56: vikash.mz23@bitsathy.ac.in
A57: 56 | B57: 7376231MZ148 | C57: SIVASAKTHI G | D57: Mechatronics Engineering | E57: 9345127824 | F57: sivasakthi.mz23@bitsathy.ac.in
A58: 57 | B58: 7376231MZ113 | C58: HARIKRISHNAN M | D58: Mechatronics Engineering | E58: 8148295257 | F58: harikrishnanm.mz23@bitsathy.ac.in
A59: 58 | B59: 7376231MZ138 | C59: REGIN L | D59: Mechatronics Engineering | E59: 7010173046 | F59: reginl.mz23@bitsathy.ac.in
A60: 59 | B60: 7376231MZ151 | C60: Sudharsan R | D60: Mechatronics Engineering | E60: 6381293569 | F60: sudharsan.mz23@bitsathy.ac.in

Sheet Round 2
A1: S.no | B1: Reg.No | C1: Name | D1: Department | E1: Mobile No. | F1: College Email ID
A2: 1 | B2: 7376231ME105 | C2: {=_xlfn.XLOOKUP(B2,'Round 1'!B:B,'Round 1'!C:C,"")} -> Bharath A S | D2: {=_xlfn.XLOOKUP(B2,'Round 1'!B:B,'Round 1'!D:D)} -> Mechanical Engineering | E2: {=_xlfn.XLOOKUP(B2,'Round 1'!B:B,'Round 1'!E:E)} -> 7418754320 | F2: {=_xlfn.XLOOKUP(B2,'Round 1'!B:B,'Round 1'!F:F,"")} -> bharath.me23@bitsathy.ac.in
A3: 2 | B3: 7376231ME108 | C3: {=_xlfn.XLOOKUP(B3,'Round 1'!B:B,'Round 1'!C:C,"")} -> Darshana Sree Jm | D3: {=_xlfn.XLOOKUP(B3,'Round 1'!B:B,'Round 1'!D:D)} -> Mechanical Engineering | E3: {=_xlfn.XLOOKUP(B3,'Round 1'!B:B,'Round 1'!E:E)} -> 9487756173 | F3: {=_xlfn.XLOOKUP(B3,'Round 1'!B:B,'Round 1'!F:F,"")} -> darshanasree.me23@bitsathy.ac.in
A4: 3 | B4: 7376231ME109 | C4: {=_xlfn.XLOOKUP(B4,'Round 1'!B:B,'Round 1'!C:C,"")} -> Deepak Venkat S | D4: {=_xlfn.XLOOKUP(B4,'Round 1'!B:B,'Round 1'!D:D)} -> Mechanical Engineering | E4: {=_xlfn.XLOOKUP(B4,'Round 1'!B:B,'Round 1'!E:E)} -> 7904914421 | F4: {=_xlfn.XLOOKUP(B4,'Round 1'!B:B,'Round 1'!F:F,"")} -> deepakvenkat.me23@bitsathy.ac.in
A5: 4 | B5: 7376231ME118 | C5: {=_xlfn.XLOOKUP(B5,'Round 1'!B:B,'Round 1'!C:C,"")} -> Guruvishnu A | D5: {=_xlfn.XLOOKUP(B5,'Round 1'!B:B,'Round 1'!D:D)} -> Mechanical Engineering | E5: {=_xlfn.XLOOKUP(B5,'Round 1'!B:B,'Round 1'!E:E)} -> 9080581929 | F5: {=_xlfn.XLOOKUP(B5,'Round 1'!B:B,'Round 1'!F:F,"")} -> guruvishnu.me23@bitsathy.ac.in
A6: 5 | B6: 7376231ME120 | C6: {=_xlfn.XLOOKUP(B6,'Round 1'!B:B,'Round 1'!C:C,"")} -> Jeyasabari S | D6: {=_xlfn.XLOOKUP(B6,'Round 1'!B:B,'Round 1'!D:D)} -> Mechanical Engineering | E6: {=_xlfn.XLOOKUP(B6,'Round 1'!B:B,'Round 1'!E:E)} -> 8248317177 | F6: {=_xlfn.XLOOKUP(B6,'Round 1'!B:B,'Round 1'!F:F,"")} -> jeyasabari.me23@bitsathy.ac.in
A7: 6 | B7: 7376231ME125 | C7: {=_xlfn.XLOOKUP(B7,'Round 1'!B:B,'Round 1'!C:C,"")} -> Malarvannan M | D7: {=_xlfn.XLOOKUP(B7,'Round 1'!B:B,'Round 1'!D:D)} -> Mechanical Engineering | E7: {=_xlfn.XLOOKUP(B7,'Round 1'!B:B,'Round 1'!E:E)} -> 8825601613 | F7: {=_xlfn.XLOOKUP(B7,'Round 1'!B:B,'Round 1'!F:F,"")} -> malarvannan.me23@bitsathy.ac.in
A8: 7 | B8: 7376231ME133 | C8: {=_xlfn.XLOOKUP(B8,'Round 1'!B:B,'Round 1'!C:C,"")} -> Njanadeepan R.K | D8: {=_xlfn.XLOOKUP(B8,'Round 1'!B:B,'Round 1'!D:D)} -> Mechanical Engineering | E8: {=_xlfn.XLOOKUP(B8,'Round 1'!B:B,'Round 1'!E:E)} -> 7373555529 | F8: {=_xlfn.XLOOKUP(B8,'Round 1'!B:B,'Round 1'!F:F,"")} -> njanadeepan.me23@bitsathy.ac.in
A9: 8 | B9: 7376241ME502 | C9: {=_xlfn.XLOOKUP(B9,'Round 1'!B:B,'Round 1'!C:C,"")} -> Priyan R S | D9: {=_xlfn.XLOOKUP(B9,'Round 1'!B:B,'Round 1'!D:D)} -> Mechanical Engineering | E9: {=_xlfn.XLOOKUP(B9,'Round 1'!B:B,'Round 1'!E:E)} -> 6374972377 | F9: {=_xlfn.XLOOKUP(B9,'Round 1'!B:B,'Round 1'!F:F,"")} -> priyanrs.me23@bitsathy.ac.in
A10: 9 | B10: 7376231ME145 | C10: {=_xlfn.XLOOKUP(B10,'Round 1'!B:B,'Round 1'!C:C,"")} -> Shanthosh S | D10: {=_xlfn.XLOOKUP(B10,'Round 1'!B:B,'Round 1'!D:D)} -> Mechanical Engineering | E10: {=_xlfn.XLOOKUP(B10,'Round 1'!B:B,'Round 1'!E:E)} -> 7305615515 | F10: {=_xlfn.XLOOKUP(B10,'Round 1'!B:B,'Round 1'!F:F,"")} -> shanthosh.me23@bitsathy.ac.in
A11: 10 | B11: 7376231ME146 | C11: {=_xlfn.XLOOKUP(B11,'Round 1'!B:B,'Round 1'!C:C,"")} -> Shyam Surgeeth S | D11: {=_xlfn.XLOOKUP(B11,'Round 1'!B:B,'Round 1'!D:D)} -> Mechanical Engineering | E11: {=_xlfn.XLOOKUP(B11,'Round 1'!B:B,'Round 1'!E:E)} -> 6385280820 | F11: {=_xlfn.XLOOKUP(B11,'Round 1'!B:B,'Round 1'!F:F,"")} -> shyamsurgeeth.me23@bitsathy.ac.in
A12: 11 | B12: 7376231ME150 | C12: {=_xlfn.XLOOKUP(B12,'Round 1'!B:B,'Round 1'!C:C,"")} -> Syed Zuhair A | D12: {=_xlfn.XLOOKUP(B12,'Round 1'!B:B,'Round 1'!D:D)} -> Mechanical Engineering | E12: {=_xlfn.XLOOKUP(B12,'Round 1'!B:B,'Round 1'!E:E)} -> 8220795566 | F12: {=_xlfn.XLOOKUP(B12,'Round 1'!B:B,'Round 1'!F:F,"")} -> syedzuhair.me23@bitsathy.ac.in
A13: 12 | B13: 7376231ME151 | C13: {=_xlfn.XLOOKUP(B13,'Round 1'!B:B,'Round 1'!C:C,"")} -> Tamizhakaran K | D13: {=_xlfn.XLOOKUP(B13,'Round 1'!B:B,'Round 1'!D:D)} -> Mechanical Engineering | E13: {=_xlfn.XLOOKUP(B13,'Round 1'!B:B,'Round 1'!E:E)} -> 9442239146 | F13: {=_xlfn.XLOOKUP(B13,'Round 1'!B:B,'Round 1'!F:F,"")} -> tamizhakaran.me23@bitsathy.ac.in
... A29: 28 | B29: 7376231ME132 | C29: {=_xlfn.XLOOKUP(B29,'Round 1'!B:B,'Round 1'!C:C,"")} -> Nithin Ananth A | D29: {=_xlfn.XLOOKUP(B29,'Round 1'!B:B,'Round 1'!D:D)} -> Mechanical Engineering | E29: {=_xlfn.XLOOKUP(B29,'Round 1'!B:B,'Round 1'!E:E)} -> 8072968340 | F29: {=_xlfn.XLOOKUP(B29,'Round 1'!B:B,'Round 1'!F:F,"")} -> nithinananth.me23@bitsathy.ac.in
A30: 29 | B30: 7376231MZ151 | C30: {=_xlfn.XLOOKUP(B30,'Round 1'!B:B,'Round 1'!C:C,"")} -> Sudharsan R | D30: {=_xlfn.XLOOKUP(B30,'Round 1'!B:B,'Round 1'!D:D)} -> Mechatronics Engineering | E30: {=_xlfn.XLOOKUP(B30,'Round 1'!B:B,'Round 1'!E:E)} -> 6381293569 | F30: sudharsan.mz23@bitsathy.ac.in
A31: 30 | B31: 7376231MZ138 | C31: {=_xlfn.XLOOKUP(B31,'Round 1'!B:B,'Round 1'!C:C,"")} -> REGIN L | D31: {=_xlfn.XLOOKUP(B31,'Round 1'!B:B,'Round 1'!D:D)} -> Mechatronics Engineering | E31: {=_xlfn.XLOOKUP(B31,'Round 1'!B:B,'Round 1'!E:E)} -> 7010173046 | F31: {=_xlfn.XLOOKUP(B31,'Round 1'!B:B,'Round 1'!F:F,"")} -> reginl.mz23@bitsathy.ac.in

Sheet Round 3
A1: S.no | B1: Reg.No | C1: Name | D1: Department | E1: Mobile No. | F1: College Email ID
A2: 1 | B2: 7376231ME105 | C2: {=_xlfn.XLOOKUP(B2,'Round 2'!B:B,'Round 2'!C:C)} -> Bharath A S | D2: {=_xlfn.XLOOKUP(B2,'Round 2'!B:B,'Round 2'!D:D)} -> Mechanical Engineering | E2: {=_xlfn.XLOOKUP(B2,'Round 2'!B:B,'Round 2'!E:E)} -> 7418754320 | F2: {=_xlfn.XLOOKUP(B2,'Round 1'!B:B,'Round 1'!F:F)} -> bharath.me23@bitsathy.ac.in
A3: 2 | B3: 7376231ME109 | C3: {=_xlfn.XLOOKUP(B3,'Round 2'!B:B,'Round 2'!C:C)} -> Deepak Venkat S | D3: {=_xlfn.XLOOKUP(B3,'Round 2'!B:B,'Round 2'!D:D)} -> Mechanical Engineering | E3: {=_xlfn.XLOOKUP(B3,'Round 2'!B:B,'Round 2'!E:E)} -> 7904914421 | F3: {=_xlfn.XLOOKUP(B3,'Round 1'!B:B,'Round 1'!F:F)} -> deepakvenkat.me23@bitsathy.ac.in
A4: 3 | B4: 7376231ME118 | C4: {=_xlfn.XLOOKUP(B4,'Round 2'!B:B,'Round 2'!C:C)} -> Guruvishnu A | D4: {=_xlfn.XLOOKUP(B4,'Round 2'!B:B,'Round 2'!D:D)} -> Mechanical Engineering | E4: {=_xlfn.XLOOKUP(B4,'Round 2'!B:B,'Round 2'!E:E)} -> 9080581929 | F4: {=_xlfn.XLOOKUP(B4,'Round 1'!B:B,'Round 1'!F:F)} -> guruvishnu.me23@bitsathy.ac.in
A5: 4 | B5: 7376241ME502 | C5: {=_xlfn.XLOOKUP(B5,'Round 2'!B:B,'Round 2'!C:C)} -> Priyan R S | D5: {=_xlfn.XLOOKUP(B5,'Round 2'!B:B,'Round 2'!D:D)} -> Mechanical Engineering | E5: {=_xlfn.XLOOKUP(B5,'Round 2'!B:B,'Round 2'!E:E)} -> 6374972377 | F5: {=_xlfn.XLOOKUP(B5,'Round 1'!B:B,'Round 1'!F:F)} -> priyanrs.me23@bitsathy.ac.in
A6: 5 | B6: 7376231ME145 | C6: {=_xlfn.XLOOKUP(B6,'Round 2'!B:B,'Round 2'!C:C)} -> Shanthosh S | D6: {=_xlfn.XLOOKUP(B6,'Round 2'!B:B,'Round 2'!D:D)} -> Mechanical Engineering | E6: {=_xlfn.XLOOKUP(B6,'Round 2'!B:B,'Round 2'!E:E)} -> 7305615515 | F6: {=_xlfn.XLOOKUP(B6,'Round 1'!B:B,'Round 1'!F:F)} -> shanthosh.me23@bitsathy.ac.in
A7: 6 | B7: 7376231ME146 | C7: {=_xlfn.XLOOKUP(B7,'Round 2'!B:B,'Round 2'!C:C)} -> Shyam Surgeeth S | D7: {=_xlfn.XLOOKUP(B7,'Round 2'!B:B,'Round 2'!D:D)} -> Mechanical Engineering | E7: {=_xlfn.XLOOKUP(B7,'Round 2'!B:B,'Round 2'!E:E)} -> 6385280820 | F7: {=_xlfn.XLOOKUP(B7,'Round 1'!B:B,'Round 1'!F:F)} -> shyamsurgeeth.me23@bitsathy.ac.in
A8: 7 | B8: 7376231ME150 | C8: {=_xlfn.XLOOKUP(B8,'Round 2'!B:B,'Round 2'!C:C)} -> Syed Zuhair A | D8: {=_xlfn.XLOOKUP(B8,'Round 2'!B:B,'Round 2'!D:D)} -> Mechanical Engineering | E8: {=_xlfn.XLOOKUP(B8,'Round 2'!B:B,'Round 2'!E:E)} -> 8220795566 | F8: {=_xlfn.XLOOKUP(B8,'Round 1'!B:B,'Round 1'!F:F)} -> syedzuhair.me23@bitsathy.ac.in
A9: 8 | B9: 7376231ME151 | C9: {=_xlfn.XLOOKUP(B9,'Round 2'!B:B,'Round 2'!C:C)} -> Tamizhakaran K | D9: {=_xlfn.XLOOKUP(B9,'Round 2'!B:B,'Round 2'!D:D)} -> Mechanical Engineering | E9: {=_xlfn.XLOOKUP(B9,'Round 2'!B:B,'Round 2'!E:E)} -> 9442239146 | F9: {=_xlfn.XLOOKUP(B9,'Round 1'!B:B,'Round 1'!F:F)} -> tamizhakaran.me23@bitsathy.ac.in
A10: 9 | B10: 7376231ME159 | C10: {=_xlfn.XLOOKUP(B10,'Round 2'!B:B,'Round 2'!C:C)} -> Vijay K R | D10: {=_xlfn.XLOOKUP(B10,'Round 2'!B:B,'Round 2'!D:D)} -> Mechanical Engineering | E10: {=_xlfn.XLOOKUP(B10,'Round 2'!B:B,'Round 2'!E:E)} -> 8300245968 | F10: {=_xlfn.XLOOKUP(B10,'Round 1'!B:B,'Round 1'!F:F)} -> vijay.me23@bitsathy.ac.in
A11: 10 | B11: 7376231MZ102 | C11: {=_xlfn.XLOOKUP(B11,'Round 2'!B:B,'Round 2'!C:C)} -> Anish T | D11: {=_xlfn.XLOOKUP(B11,'Round 2'!B:B,'Round 2'!D:D)} -> Mechatronics Engineering | E11: {=_xlfn.XLOOKUP(B11,'Round 2'!B:B,'Round 2'!E:E)} -> 8122641755 | F11: {=_xlfn.XLOOKUP(B11,'Round 1'!B:B,'Round 1'!F:F)} -> anish.mz23@bitsathy.ac.in
A12: 11 | B12: 7376231MZ121 | C12: {=_xlfn.XLOOKUP(B12,'Round 2'!B:B,'Round 2'!C:C)} -> Mathiyazhagan M | D12: {=_xlfn.XLOOKUP(B12,'Round 2'!B:B,'Round 2'!D:D)} -> Mechatronics Engineering | E12: {=_xlfn.XLOOKUP(B12,'Round 2'!B:B,'Round 2'!E:E)} -> 9944196743 | F12: {=_xlfn.XLOOKUP(B12,'Round 1'!B:B,'Round 1'!F:F)} -> mathiyazhagan.mz23@bitsathy.ac.in
A13: 12 | B13: 7376231MZ123 | C13: {=_xlfn.XLOOKUP(B13,'Round 2'!B:B,'Round 2'!C:C)} -> Mohammed Shameem A | D13: {=_xlfn.XLOOKUP(B13,'Round 2'!B:B,'Round 2'!D:D)} -> Mechatronics Engineering | E13: {=_xlfn.XLOOKUP(B13,'Round 2'!B:B,'Round 2'!E:E)} -> 9344912048 | F13: {=_xlfn.XLOOKUP(B13,'Round 1'!B:B,'Round 1'!F:F)} -> mohammedshameem.mz23@bitsathy.ac.in
... A20: 19 | B20: 7376231ME135 | C20: {=_xlfn.XLOOKUP(B20,'Round 2'!B:B,'Round 2'!C:C)} -> Padmaprajesh S B | D20: {=_xlfn.XLOOKUP(B20,'Round 2'!B:B,'Round 2'!D:D)} -> Mechanical Engineering | E20: {=_xlfn.XLOOKUP(B20,'Round 2'!B:B,'Round 2'!E:E)} -> 7530061995 | F20: {=_xlfn.XLOOKUP(B20,'Round 1'!B:B,'Round 1'!F:F)} -> padmaprajeshsb.me23@bitsathy.ac.in
A21: 20 | B21: 7376231MZ151 | C21: {=_xlfn.XLOOKUP(B21,'Round 2'!B:B,'Round 2'!C:C)} -> Sudharsan R | D21: {=_xlfn.XLOOKUP(B21,'Round 2'!B:B,'Round 2'!D:D)} -> Mechatronics Engineering | E21: {=_xlfn.XLOOKUP(B21,'Round 2'!B:B,'Round 2'!E:E)} -> 6381293569 | F21: sudharsan.mz23@bitsathy.ac.in

Sheet Offer
A1: S.no | B1: Reg.No | C1: Name | D1: Department | E1: Mobile No. | F1: College Email ID
A2: 1 | B2: 7376231ME105 | C2: {=_xlfn.XLOOKUP(B2,'Round 2'!B:B,'Round 2'!C:C)} -> Bharath A S | D2: {=_xlfn.XLOOKUP(B2,'Round 2'!B:B,'Round 2'!D:D)} -> Mechanical Engineering | E2: {=_xlfn.XLOOKUP(B2,'Round 2'!B:B,'Round 2'!E:E)} -> 7418754320 | F2: {=_xlfn.XLOOKUP(B2,'Round 1'!B:B,'Round 1'!F:F)} -> bharath.me23@bitsathy.ac.in
A3: 2 | B3: 7376231ME109 | C3: {=_xlfn.XLOOKUP(B3,'Round 2'!B:B,'Round 2'!C:C)} -> Deepak Venkat S | D3: {=_xlfn.XLOOKUP(B3,'Round 2'!B:B,'Round 2'!D:D)} -> Mechanical Engineering | E3: {=_xlfn.XLOOKUP(B3,'Round 2'!B:B,'Round 2'!E:E)} -> 7904914421 | F3: {=_xlfn.XLOOKUP(B3,'Round 1'!B:B,'Round 1'!F:F)} -> deepakvenkat.me23@bitsathy.ac.in
A4: 3 | B4: 7376231ME118 | C4: {=_xlfn.XLOOKUP(B4,'Round 2'!B:B,'Round 2'!C:C)} -> Guruvishnu A | D4: {=_xlfn.XLOOKUP(B4,'Round 2'!B:B,'Round 2'!D:D)} -> Mechanical Engineering | E4: {=_xlfn.XLOOKUP(B4,'Round 2'!B:B,'Round 2'!E:E)} -> 9080581929 | F4: {=_xlfn.XLOOKUP(B4,'Round 1'!B:B,'Round 1'!F:F)} -> guruvishnu.me23@bitsathy.ac.in
A5: 4 | B5: 7376241ME502 | C5: {=_xlfn.XLOOKUP(B5,'Round 2'!B:B,'Round 2'!C:C)} -> Priyan R S | D5: {=_xlfn.XLOOKUP(B5,'Round 2'!B:B,'Round 2'!D:D)} -> Mechanical Engineering | E5: {=_xlfn.XLOOKUP(B5,'Round 2'!B:B,'Round 2'!E:E)} -> 6374972377 | F5: {=_xlfn.XLOOKUP(B5,'Round 1'!B:B,'Round 1'!F:F)} -> priyanrs.me23@bitsathy.ac.in
A6: 5 | B6: 7376231ME145 | C6: {=_xlfn.XLOOKUP(B6,'Round 2'!B:B,'Round 2'!C:C)} -> Shanthosh S | D6: {=_xlfn.XLOOKUP(B6,'Round 2'!B:B,'Round 2'!D:D)} -> Mechanical Engineering | E6: {=_xlfn.XLOOKUP(B6,'Round 2'!B:B,'Round 2'!E:E)} -> 7305615515 | F6: {=_xlfn.XLOOKUP(B6,'Round 1'!B:B,'Round 1'!F:F)} -> shanthosh.me23@bitsathy.ac.in
A7: 6 | B7: 7376231ME146 | C7: {=_xlfn.XLOOKUP(B7,'Round 2'!B:B,'Round 2'!C:C)} -> Shyam Surgeeth S | D7: {=_xlfn.XLOOKUP(B7,'Round 2'!B:B,'Round 2'!D:D)} -> Mechanical Engineering | E7: {=_xlfn.XLOOKUP(B7,'Round 2'!B:B,'Round 2'!E:E)} -> 6385280820 | F7: {=_xlfn.XLOOKUP(B7,'Round 1'!B:B,'Round 1'!F:F)} -> shyamsurgeeth.me23@bitsathy.ac.in
A8: 7 | B8: 7376231ME150 | C8: {=_xlfn.XLOOKUP(B8,'Round 2'!B:B,'Round 2'!C:C)} -> Syed Zuhair A | D8: {=_xlfn.XLOOKUP(B8,'Round 2'!B:B,'Round 2'!D:D)} -> Mechanical Engineering | E8: {=_xlfn.XLOOKUP(B8,'Round 2'!B:B,'Round 2'!E:E)} -> 8220795566 | F8: {=_xlfn.XLOOKUP(B8,'Round 1'!B:B,'Round 1'!F:F)} -> syedzuhair.me23@bitsathy.ac.in
A9: 8 | B9: 7376231ME151 | C9: {=_xlfn.XLOOKUP(B9,'Round 2'!B:B,'Round 2'!C:C)} -> Tamizhakaran K | D9: {=_xlfn.XLOOKUP(B9,'Round 2'!B:B,'Round 2'!D:D)} -> Mechanical Engineering | E9: {=_xlfn.XLOOKUP(B9,'Round 2'!B:B,'Round 2'!E:E)} -> 9442239146 | F9: {=_xlfn.XLOOKUP(B9,'Round 1'!B:B,'Round 1'!F:F)} -> tamizhakaran.me23@bitsathy.ac.in
A10: 9 | B10: 7376231ME159 | C10: {=_xlfn.XLOOKUP(B10,'Round 2'!B:B,'Round 2'!C:C)} -> Vijay K R | D10: {=_xlfn.XLOOKUP(B10,'Round 2'!B:B,'Round 2'!D:D)} -> Mechanical Engineering | E10: {=_xlfn.XLOOKUP(B10,'Round 2'!B:B,'Round 2'!E:E)} -> 8300245968 | F10: {=_xlfn.XLOOKUP(B10,'Round 1'!B:B,'Round 1'!F:F)} -> vijay.me23@bitsathy.ac.in
A11: 10 | B11: 7376231MZ102 | C11: {=_xlfn.XLOOKUP(B11,'Round 2'!B:B,'Round 2'!C:C)} -> Anish T | D11: {=_xlfn.XLOOKUP(B11,'Round 2'!B:B,'Round 2'!D:D)} -> Mechatronics Engineering | E11: {=_xlfn.XLOOKUP(B11,'Round 2'!B:B,'Round 2'!E:E)} -> 8122641755 | F11: {=_xlfn.XLOOKUP(B11,'Round 1'!B:B,'Round 1'!F:F)} -> anish.mz23@bitsathy.ac.in
A12: 11 | B12: 7376231MZ121 | C12: {=_xlfn.XLOOKUP(B12,'Round 2'!B:B,'Round 2'!C:C)} -> Mathiyazhagan M | D12: {=_xlfn.XLOOKUP(B12,'Round 2'!B:B,'Round 2'!D:D)} -> Mechatronics Engineering | E12: {=_xlfn.XLOOKUP(B12,'Round 2'!B:B,'Round 2'!E:E)} -> 9944196743 | F12: {=_xlfn.XLOOKUP(B12,'Round 1'!B:B,'Round 1'!F:F)} -> mathiyazhagan.mz23@bitsathy.ac.in
A13: 12 | B13: 7376231MZ123 | C13: {=_xlfn.XLOOKUP(B13,'Round 2'!B:B,'Round 2'!C:C)} -> Mohammed Shameem A | D13: {=_xlfn.XLOOKUP(B13,'Round 2'!B:B,'Round 2'!D:D)} -> Mechatronics Engineering | E13: {=_xlfn.XLOOKUP(B13,'Round 2'!B:B,'Round 2'!E:E)} -> 9344912048 | F13: {=_xlfn.XLOOKUP(B13,'Round 1'!B:B,'Round 1'!F:F)} -> mohammedshameem.mz23@bitsathy.ac.in
... A20: 19 | B20: 7376231ME135 | C20: {=_xlfn.XLOOKUP(B20,'Round 2'!B:B,'Round 2'!C:C)} -> Padmaprajesh S B | D20: {=_xlfn.XLOOKUP(B20,'Round 2'!B:B,'Round 2'!D:D)} -> Mechanical Engineering | E20: {=_xlfn.XLOOKUP(B20,'Round 2'!B:B,'Round 2'!E:E)} -> 7530061995 | F20: {=_xlfn.XLOOKUP(B20,'Round 1'!B:B,'Round 1'!F:F)} -> padmaprajeshsb.me23@bitsathy.ac.in
A21: 20 | B21: 7376231MZ151 | C21: {=_xlfn.XLOOKUP(B21,'Round 2'!B:B,'Round 2'!C:C)} -> Sudharsan R | D21: {=_xlfn.XLOOKUP(B21,'Round 2'!B:B,'Round 2'!D:D)} -> Mechatronics Engineering | E21: {=_xlfn.XLOOKUP(B21,'Round 2'!B:B,'Round 2'!E:E)} -> 6381293569 | F21: sudharsan.mz23@bitsathy.ac.in
